<mujoco model="g1_task">
  <include file="g1_29dof.xml"/>
  
  <statistic center="0 0 0.1" extent="0.8"/>
  
  <visual>
    <headlight diffuse="0.6 0.6 0.6" ambient="0.3 0.3 0.3" specular="0 0 0"/>
    <rgba haze="0.15 0.25 0.35 1"/>
    <global azimuth="-130" elevation="-20"/>
  </visual>

  <asset>
    <texture type="skybox" builtin="gradient" rgb1="0.3 0.5 0.7" rgb2="0 0 0" width="512" height="3072"/>
    <texture type="2d" name="groundplane" builtin="checker" mark="edge" rgb1="0.2 0.3 0.4" rgb2="0.1 0.2 0.3"
      markrgb="0.8 0.8 0.8" width="300" height="300"/>
    <material name="groundplane" texture="groundplane" texuniform="true" texrepeat="5 5" reflectance="0.2"/>
    <material name="table_mat" rgba="0.6 0.3 0.1 1"/>
    <material name="box_red" rgba="0.9 0.1 0.1 1"/>
    <material name="box_green" rgba="0.1 0.9 0.1 1"/>
    <material name="target_mat" rgba="0.1 0.1 0.8 0.5"/>
  </asset>

  <worldbody>
    <light pos="0 0 1.5" dir="0 0 -1" directional="true"/>
    <geom name="floor" type="plane" size="5 5 0.1" material="groundplane"/>

    <body name="source_table" pos="1.5 1.5 0.5" euler="0 0 -1.57">
      <geom name="source_table_top" type="box" size="0.5 0.5 0.02" pos="0 0 0.02" material="table_mat"/>
      <geom name="source_table_leg" type="box" size="0.05 0.05 0.5" pos="0 0 -0.25" material="table_mat"/>
      
      <body name="box1" pos="0.1 -0.4 0.04">
        <joint name="box1_x" type="slide" axis="1 0 0" range="-0.5 0.5"/>
        <joint name="box1_y" type="slide" axis="0 1 0" range="-0.5 0.5"/>
        <geom name="box1_geom" type="box" size="0.05 0.05 0.05" material="box_red" mass="0.1"/>
        <site name="box1_site" pos="0 0 0" size="0.01 0.01 0.01" rgba="1 0 0 0.5"/>
      </body>
      
      <body name="box2" pos="-0.1 -0.4 0.04">
        <joint name="box2_x" type="slide" axis="1 0 0" range="-0.5 0.5"/>
        <joint name="box2_y" type="slide" axis="0 1 0" range="-0.5 0.5"/>
        <geom name="box2_geom" type="box" size="0.05 0.05 0.05" material="box_green" mass="0.1"/>
        <site name="box2_site" pos="0 0 0" size="0.01 0.01 0.01" rgba="0 1 0 0.5"/>
      </body>
    </body>

    <body name="target_table" pos="1.5 -1.5 0.5" euler="0 0 -1.57">
      <geom name="target_table_top" type="box" size="0.5 0.5 0.02" pos="0 0 0.02" material="table_mat"/>
      <geom name="target_table_leg" type="box" size="0.05 0.05 0.5" pos="0 0 -0.25" material="table_mat"/>
      
      <body name="target1" pos="0.2 -0.4 0.04">
        <geom name="target1_zone" type="box" size="0.1 0.1 0.001" material="target_mat"/>
        <site name="target1_site" pos="0 0 0" size="0.01 0.01 0.01" rgba="1 0 0 0.5"/>
      </body>
      
      <body name="target2" pos="-0.2 -0.4 0.04">
        <geom name="target2_zone" type="box" size="0.1 0.1 0.001" material="target_mat"/>
        <site name="target2_site" pos="0 0 0" size="0.01 0.01 0.01" rgba="0 1 0 0.5"/>
      </body>
    </body>
  </worldbody>

  <sensor>
    <framepos name="box1_pos" objtype="site" objname="box1_site"/>
    <framepos name="box2_pos" objtype="site" objname="box2_site"/>
    <framepos name="target1_pos" objtype="site" objname="target1_site"/>
    <framepos name="target2_pos" objtype="site" objname="target2_site"/>
  </sensor>
</mujoco>